Workbook

Sheet Lisez-moi
A1: DOGZIE UNIVERSE — Projections de revenus (ILLUSTRATIVES)
A2: Dogzie Universe (couche blockchain) + Dogzie Town (console PlayStation) + jeton Dogzy. Ancien nom : Family Universe.
A4: Comment lire ces chiffres
A5: • Ce sont des scénarios illustratifs pour discuter avec des investisseurs. Pas une prévision, pas une garantie, pas un audit.
A6: • Les contrats intelligents (DogzyToken, PontDogzy) sont rédigés, mais NON déployés et NON audités. Le jeton Dogzy n'est inscrit sur aucune plateforme d'échange.
A7: • Toute fonction blockchain exige : déploiement, audit de sécurité indépendant, validation juridique (AMF / ACVM) et validation des règles de Sony PlayStation.
A8: • Aucune valeur de jeton ni capitalisation n'est projetée. Les volets crypto sont modélisés en $ CA au moment de la vente (frais / prise de plateforme seulement).
A9: • Le capital recherché pour la Phase 2 (500 000 $ à 550 000 $ CA) est un INVESTISSEMENT, pas un revenu. Il n'est inclus dans aucun total.
A10: • An 1 = 12 premiers mois après le lancement commercial de Dogzie Town. Devise : $ CA partout.
A11: • « Revenu net » = après part PlayStation, commissions de galeries, coût de la marchandise et redevances influenceurs. AVANT salaires, serveurs, développement, marketing payé et impôts. Ce n'est pas un profit.
A13: Structure du classeur
A14: Hypothèses : toutes les hypothèses (cellules dorées = modifiables). Les feuilles de calcul se mettent à jour automatiquement.
... A24: Volatilité crypto : la valeur en $ CA d'un montant en Dogzy, BNB ou AVAX peut varier fortement entre l'achat et la conversion. Les revenus encaissés en crypto ne sont pas garantis en $ CA.

Sheet Sommaire
A1: Sommaire — Dogzie Universe (illustratif, $ CA)
A2: Scénarios : Prudent · Normal · « Si le concept pogne vraiment » (Optimiste)
A4: Revenu BRUT total
A5: Scénario | B5: An 1 | C5: Cumul 3 ans | D5: Cumul 5 ans | E5: An 3 (annuel) | F5: An 5 (annuel)
A6: Prudent | B6: =Prudent!C30 -> 128482.2 | C6: =Prudent!H30 -> 493500.33 | D6: =Prudent!I30 -> 947675.13 | E6: =Prudent!E30 -> 200650.12 | F6: =Prudent!G30 -> 246156.75
A7: Normal | B7: =Normal!C30 -> 571159.5 | C7: =Normal!H30 -> 2629619.5 | D7: =Normal!I30 -> 5829127.7 | E7: =Normal!E30 -> 1202091.9 | F7: =Normal!G30 -> 1733850.4
A8: Optimiste (« si ça pogne vraiment ») | B8: =Optimiste!C30 -> 2331292.5 | C8: =Optimiste!H30 -> 13931632 | D8: =Optimiste!I30 -> 35121925 | E8: =Optimiste!E30 -> 7077564.1 | F8: =Optimiste!G30 -> 11685201
A10: Revenu NET pour l'entreprise (avant dépenses d'exploitation)
A11: Scénario | B11: An 1 | C11: Cumul 3 ans | D11: Cumul 5 ans | E11: An 3 (annuel) | F11: An 5 (annuel)
A12: Prudent | B12: =Prudent!C35 -> 92842.71 | C12: =Prudent!H35 -> 353024.73 | D12: =Prudent!I35 -> 677599.25 | E12: =Prudent!E35 -> 142714.78 | F12: =Prudent!G35 -> 175755.92
A13: Normal | B13: =Normal!C35 -> 402050.47 | C13: =Normal!H35 -> 1851929 | D13: =Normal!I35 -> 4144762.5 | E13: =Normal!E35 -> 849038.57 | F13: =Normal!G35 -> 1247418.4
A14: Optimiste (« si ça pogne vraiment ») | B14: =Optimiste!C35 -> 1634488.9 | C14: =Optimiste!H35 -> 9848668.7 | D14: =Optimiste!I35 -> 25247615 | E14: =Optimiste!E35 -> 5037970.6 | F14: =Optimiste!G35 -> 8540563.9
A16: Revenu brut cumulatif 5 ans par volet
A17: Volet | B17: Prudent | C17: Normal | D17: Optimiste
A18: A. Console — Dogzie Town | B18: =Prudent!I11 -> 655934.6 | C18: =Normal!I11 -> 4530014.3 | D18: =Optimiste!I11 -> 27638291
A19: B. Blockchain — Dogzie Universe | B19: =Prudent!I21 -> 176596.43 | C19: =Normal!I21 -> 727690.53 | D19: =Optimiste!I21 -> 3911842.3
A20: C. Art physique — Galerie Valkyrie | B20: =Prudent!I24 -> 91500 | C20: =Normal!I24 -> 181500 | D20: =Optimiste!I24 -> 370500
A21: D. Marchandise / marque | B21: =Prudent!I26 -> 12306.058 | C21: =Normal!I26 -> 164363.38 | D21: =Optimiste!I26 -> 1422118.9
A22: E. Lieux thématiques (expansions) | B22: =Prudent!I28 -> 11338.033 | C22: =Normal!I28 -> 225559.58 | D22: =Optimiste!I28 -> 1779172.7
A24: Joueurs actifs — An 1 / An 3 / An 5
A25: Scénario | B25: An 1 | C25: An 3 | D25: An 5
A26: Prudent | B26: =Prudent!C5 -> 3000 | C26: =Prudent!E5 -> 6767.5 | D26: =Prudent!G5 -> 8579.0187
A27: Normal | B27: =Normal!C5 -> 15000 | C27: =Normal!E5 -> 42937.5 | D27: =Normal!G5 -> 64444.844
A28: Optimiste | B28: =Optimiste!C5 -> 60000 | C28: =Optimiste!E5 -> 238650 | D28: =Optimiste!G5 -> 412191.62
A30: Capital Phase 2 recherché : 500 000 $ – 550 000 $ CA = investissement, exclu de tous les totaux.
A31: ILLUSTRATIF · non audité · pas une garantie · contrats non déployés ni audités · jeton Dogzy non inscrit.

Sheet Hypothèses
A1: Hypothèses — modifiez les cellules dorées
A3: Hypothèse | B3: Unité | C3: Prudent | D3: Normal | E3: Optimiste | F3: Note
A4: 1. Joueurs (Dogzie Town, console)
A5: Nouveaux joueurs (achats du jeu) — An 1 | B5: joueurs | C5: 3000 | D5: 15000 | E5: 60000 | F5: Copies vendues dans l'année
A6: Nouveaux joueurs — An 2 | B6: joueurs | C6: 4000 | D6: 22000 | E6: 110000
A7: Nouveaux joueurs — An 3 | B7: joueurs | C7: 5000 | D7: 30000 | E7: 160000
A8: Nouveaux joueurs — An 4 | B8: joueurs | C8: 5000 | D8: 35000 | E8: 200000
A9: Nouveaux joueurs — An 5 | B9: joueurs | C9: 6000 | D9: 40000 | E9: 230000
A10: Rétention annuelle des joueurs actifs | B10: % | C10: 0.35 | D10: 0.45 | E10: 0.55 | F10: Part des joueurs d'une année qui restent actifs l'année suivante
A11: 2. Prix (identiques dans les 3 scénarios, $ CA)
A12: Prix moyen réalisé du jeu (après soldes) | B12: $ | C12: 24.99 | D12: 24.99 | E12: 24.99 | F12: Prix affiché visé ~29,99 $; soldes incluses
A13: Prix d'une extension (DLC) | B13: $ | C13: 9.99 | D13: 9.99 | E13: 9.99 | F13: 5 extensions prévues : 1 par année
A14: Extensions lancées par année | B14: nb | C14: 1 | D14: 1 | E14: 1
A15: Passe compétitive multijoueur (par année) | B15: $ | C15: 7.99 | D15: 7.99 | E15: 7.99 | F15: Duel 2 joueurs, camps toujours opposés
A16: Dépense annuelle moyenne en accessoires (payée en Dogzy) | B16: $ | C16: 30 | D16: 30 | E16: 30 | F16: Valeur en $ CA au moment de l'achat
A17: Prix moyen d'un NFT personnage | B17: $ | C17: 75 | D17: 75 | E17: 75 | F17: 143 personnages; éditions à définir
A18: Prix moyen d'un lot NFT bâtiment / carte | B18: $ | C18: 350 | D18: 350 | E18: 350 | F18: 46 bâtiments x 5 éditions = 230 lots de base
A19: Prix moyen d'une édition NFT Valkyrie (collection mensuelle) | B19: $ | C19: 100 | D19: 100 | E19: 100
A20: Prix moyen d'une toile physique | B20: $ | C20: 1500 | D20: 1500 | E20: 1500 | F20: À confirmer avec l'historique de ventes réel
A21: Panier moyen marchandise | B21: $ | C21: 40 | D21: 40 | E21: 40
A22: Passe NFT d'un lieu thématique (par lieu, par année) | B22: $ | C22: 12 | D22: 12 | E22: 12 | F22: Croisière, événements sportifs, casino-lieu (sans jeu d'argent)
A23: 3. Conversions et volumes (ce qui change d'un scénario à l'autre)
A24: Joueurs actifs qui achètent l'extension de l'année | B24: % | C24: 0.15 | D24: 0.25 | E24: 0.35
A25: Joueurs actifs qui achètent la passe compétitive | B25: % | C25: 0.03 | D25: 0.06 | E25: 0.1
A26: Joueurs actifs qui achètent des accessoires en Dogzy | B26: % | C26: 0.03 | D26: 0.06 | E26: 0.1 | F26: Exige un portefeuille : conversion volontairement basse
A27: Joueurs actifs qui achètent un NFT personnage dans l'année | B27: % | C27: 0.01 | D27: 0.02 | E27: 0.03
A28: Acheteurs NFT venant du milieu crypto (hors joueurs) / an | B28: nb | C28: 150 | D28: 300 | E28: 600
A29: Lots NFT bâtiments / carte vendus par année | B29: nb | C29: 10 | D29: 25 | E29: 45 | F29: Max 5 ans : 225 lots ≤ 230 de base
A30: Éditions Valkyrie vendues par collection mensuelle — An 1 | B30: nb | C30: 10 | D30: 25 | E30: 60 | F30: 12 collections par année
A31: Croissance annuelle des éditions Valkyrie | B31: % | C31: 0.1 | D31: 0.2 | E31: 0.3
A32: Toiles physiques vendues — An 1 | B32: nb | C32: 10 | D32: 18 | E32: 30 | F32: Repère fondatrice : 37 toiles dans le monde à ce jour
A33: Croissance annuelle des ventes de toiles | B33: % | C33: 0.1 | D33: 0.15 | E33: 0.25
A34: Joueurs actifs qui achètent de la marchandise | B34: % | C34: 0.01 | D34: 0.02 | E34: 0.03
A35: Joueurs actifs qui achètent la passe d'un lieu thématique | B35: % | C35: 0.02 | D35: 0.04 | E35: 0.06
A36: Commandites par lieu thématique actif / an | B36: $ | C36: 0 | D36: 10000 | E36: 40000
A37: Revente secondaire annuelle (% de la valeur NFT primaire cumulée) | B37: % | C37: 0.25 | D37: 0.4 | E37: 0.6
A38: Détenteurs (perso. dans Universe ET Town) qui exportent des jetons | B38: % | C38: 0.3 | D38: 0.4 | E38: 0.5
A39: 4. Taux, frais et déductions
A40: Redevance sur reventes NFT secondaires | B40: % | C40: 0.05 | D40: 0.05 | E40: 0.05
A41: Valeur moyenne exportée par détenteur / an | B41: $ | C41: 20 | D41: 20 | E41: 20 | F41: Ex. 500 000 jetons de jeu ↔ 5 Dogzy, selon la valeur
...

Sheet Prudent
A1: Scénario Prudent — calcul détaillé ($ CA)
A3: Poste | B3: Réf. | C3: An 1 | D3: An 2 | E3: An 3 | F3: An 4 | G3: An 5 | H3: Cumul 3 ans | I3: Cumul 5 ans
A4: Nouveaux joueurs | B4: new | C4: =Hypothèses!$C$5 -> 3000 | D4: =Hypothèses!$C$6 -> 4000 | E4: =Hypothèses!$C$7 -> 5000 | F4: =Hypothèses!$C$8 -> 5000 | G4: =Hypothèses!$C$9 -> 6000
A5: Joueurs actifs (année précédente x rétention + nouveaux) | B5: active | C5: =C4 -> 3000 | D5: =C5*Hypothèses!$C$10+D4 -> 5050 | E5: =D5*Hypothèses!$C$10+E4 -> 6767.5 | F5: =E5*Hypothèses!$C$10+F4 -> 7368.625 | G5: =F5*Hypothèses!$C$10+G4 -> 8579.0187
A6: A. CONSOLE — DOGZIE TOWN
A7: Ventes du jeu | B7: A1 | C7: =C4*Hypothèses!$C$12 -> 74970 | D7: =D4*Hypothèses!$C$12 -> 99960 | E7: =E4*Hypothèses!$C$12 -> 124950 | F7: =F4*Hypothèses!$C$12 -> 124950 | G7: =G4*Hypothèses!$C$12 -> 149940 | H7: =SUM(C7:E7) -> 299880 | I7: =SUM(C7:G7) -> 574770
A8: Extensions (DLC) | B8: A2 | C8: =C5*Hypothèses!$C$24*Hypothèses!$C$13*Hypothèses!$C$14 -> 4495.5 | D8: =D5*Hypothèses!$C$24*Hypothèses!$C$13*Hypothèses!$C$14 -> 7567.425 | E8: =E5*Hypothèses!$C$24*Hypothèses!$C$13*Hypothèses!$C$14 -> 10141.099 | F8: =F5*Hypothèses!$C$24*Hypothèses!$C$13*Hypothèses!$C$14 -> 11041.885 | G8: =G5*Hypothèses!$C$24*Hypothèses!$C$13*Hypothèses!$C$14 -> 12855.66 | H8: =SUM(C8:E8) -> 22204.024 | I8: =SUM(C8:G8) -> 46101.568
A9: Passe compétitive multijoueur | B9: A3 | C9: =C5*Hypothèses!$C$25*Hypothèses!$C$15 -> 719.1 | D9: =D5*Hypothèses!$C$25*Hypothèses!$C$15 -> 1210.485 | E9: =E5*Hypothèses!$C$25*Hypothèses!$C$15 -> 1622.1698 | F9: =F5*Hypothèses!$C$25*Hypothèses!$C$15 -> 1766.2594 | G9: =G5*Hypothèses!$C$25*Hypothèses!$C$15 -> 2056.3908 | H9: =SUM(C9:E9) -> 3551.7548 | I9: =SUM(C9:G9) -> 7374.405
A10: Accessoires / cosmétiques (payés en Dogzy, valeur $ CA) | B10: A4 | C10: =C5*Hypothèses!$C$26*Hypothèses!$C$16 -> 2700 | D10: =D5*Hypothèses!$C$26*Hypothèses!$C$16 -> 4545 | E10: =E5*Hypothèses!$C$26*Hypothèses!$C$16 -> 6090.75 | F10: =F5*Hypothèses!$C$26*Hypothèses!$C$16 -> 6631.7625 | G10: =G5*Hypothèses!$C$26*Hypothèses!$C$16 -> 7721.1169 | H10: =SUM(C10:E10) -> 13335.75 | I10: =SUM(C10:G10) -> 27688.629
A11: Total A | B11: A | C11: =SUM(C7:C10) -> 82884.6 | D11: =SUM(D7:D10) -> 113282.91 | E11: =SUM(E7:E10) -> 142804.02 | F11: =SUM(F7:F10) -> 144389.91 | G11: =SUM(G7:G10) -> 172573.17 | H11: =SUM(C11:E11) -> 338971.53 | I11: =SUM(C11:G11) -> 655934.6
A12: B. BLOCKCHAIN — DOGZIE UNIVERSE
A13: NFT personnages vendus (nb) | B13: B1m | C13: =C5*Hypothèses!$C$27+Hypothèses!$C$28 -> 180 | D13: =D5*Hypothèses!$C$27+Hypothèses!$C$28 -> 200.5 | E13: =E5*Hypothèses!$C$27+Hypothèses!$C$28 -> 217.675 | F13: =F5*Hypothèses!$C$27+Hypothèses!$C$28 -> 223.68625 | G13: =G5*Hypothèses!$C$27+Hypothèses!$C$28 -> 235.79019
A14: Détenteurs cumulés (nb) | B14: hold | C14: =C13 -> 180 | D14: =C14+D13 -> 380.5 | E14: =D14+E13 -> 598.175 | F14: =E14+F13 -> 821.86125 | G14: =F14+G13 -> 1057.6514
A15: NFT personnages | B15: B1 | C15: =C13*Hypothèses!$C$17 -> 13500 | D15: =D13*Hypothèses!$C$17 -> 15037.5 | E15: =E13*Hypothèses!$C$17 -> 16325.625 | F15: =F13*Hypothèses!$C$17 -> 16776.469 | G15: =G13*Hypothèses!$C$17 -> 17684.264 | H15: =SUM(C15:E15) -> 44863.125 | I15: =SUM(C15:G15) -> 79323.858
A16: NFT bâtiments / carte | B16: B2 | C16: =Hypothèses!$C$29*Hypothèses!$C$18 -> 3500 | D16: =Hypothèses!$C$29*Hypothèses!$C$18 -> 3500 | E16: =Hypothèses!$C$29*Hypothèses!$C$18 -> 3500 | F16: =Hypothèses!$C$29*Hypothèses!$C$18 -> 3500 | G16: =Hypothèses!$C$29*Hypothèses!$C$18 -> 3500 | H16: =SUM(C16:E16) -> 10500 | I16: =SUM(C16:G16) -> 17500
A17: Éditions Valkyrie par collection (nb) | B17: B3e | C17: =ROUND(Hypothèses!$C$30*(1+Hypothèses!$C$31)^0,0) -> 10 | D17: =ROUND(Hypothèses!$C$30*(1+Hypothèses!$C$31)^1,0) -> 11 | E17: =ROUND(Hypothèses!$C$30*(1+Hypothèses!$C$31)^2,0) -> 12 | F17: =ROUND(Hypothèses!$C$30*(1+Hypothèses!$C$31)^3,0) -> 13 | G17: =ROUND(Hypothèses!$C$30*(1+Hypothèses!$C$31)^4,0) -> 15
A18: Collections NFT mensuelles Valkyrie (12 / an) | B18: B3 | C18: =12*C17*Hypothèses!$C$19 -> 12000 | D18: =12*D17*Hypothèses!$C$19 -> 13200 | E18: =12*E17*Hypothèses!$C$19 -> 14400 | F18: =12*F17*Hypothèses!$C$19 -> 15600 | G18: =12*G17*Hypothèses!$C$19 -> 18000 | H18: =SUM(C18:E18) -> 39600 | I18: =SUM(C18:G18) -> 73200
A19: Redevances sur reventes secondaires | B19: B4 | C19: =(SUM($C15:C15)+SUM($C16:C16)+SUM($C18:C18))*Hypothèses!$C$37*Hypothèses!$C$40 -> 362.5 | D19: =(SUM($C15:D15)+SUM($C16:D16)+SUM($C18:D18))*Hypothèses!$C$37*Hypothèses!$C$40 -> 759.21875 | E19: =(SUM($C15:E15)+SUM($C16:E16)+SUM($C18:E18))*Hypothèses!$C$37*Hypothèses!$C$40 -> 1187.0391 | F19: =(SUM($C15:F15)+SUM($C16:F16)+SUM($C18:F18))*Hypothèses!$C$37*Hypothèses!$C$40 -> 1635.4949 | G19: =(SUM($C15:G15)+SUM($C16:G16)+SUM($C18:G18))*Hypothèses!$C$37*Hypothèses!$C$40 -> 2125.2982 | H19: =SUM(C19:E19) -> 2308.7578 | I19: =SUM(C19:G19) -> 6069.551
A20: Frais de plateforme (export de jetons + revente d'accessoires) | B20: B5 | C20: =C14*Hypothèses!$C$38*Hypothèses!$C$41*Hypothèses!$C$42+C10*Hypothèses!$C$43*Hypothèses!$C$44 -> 35.1 | D20: =D14*Hypothèses!$C$38*Hypothèses!$C$41*Hypothèses!$C$42+D10*Hypothèses!$C$43*Hypothèses!$C$44 -> 68.385 | E20: =E14*Hypothèses!$C$38*Hypothèses!$C$41*Hypothèses!$C$42+E10*Hypothèses!$C$43*Hypothèses!$C$44 -> 102.23475 | F20: =F14*Hypothèses!$C$38*Hypothèses!$C$41*Hypothèses!$C$42+F10*Hypothèses!$C$43*Hypothèses!$C$44 -> 131.78216 | G20: =G14*Hypothèses!$C$38*Hypothèses!$C$41*Hypothèses!$C$42+G10*Hypothèses!$C$43*Hypothèses!$C$44 -> 165.52376 | H20: =SUM(C20:E20) -> 205.71975 | I20: =SUM(C20:G20) -> 503.02567
A21: Total B | B21: B | C21: =C15+C16+C18+C19+C20 -> 29397.6 | D21: =D15+D16+D18+D19+D20 -> 32565.104 | E21: =E15+E16+E18+E19+E20 -> 35514.899 | F21: =F15+F16+F18+F19+F20 -> 37643.746 | G21: =G15+G16+G18+G19+G20 -> 41475.086 | H21: =SUM(C21:E21) -> 97477.603 | I21: =SUM(C21:G21) -> 176596.43
A22: C. ART PHYSIQUE — GALERIE VALKYRIE
A23: Toiles vendues (nb) | B23: Cn | C23: =ROUND(Hypothèses!$C$32*(1+Hypothèses!$C$33)^0,0) -> 10 | D23: =ROUND(Hypothèses!$C$32*(1+Hypothèses!$C$33)^1,0) -> 11 | E23: =ROUND(Hypothèses!$C$32*(1+Hypothèses!$C$33)^2,0) -> 12 | F23: =ROUND(Hypothèses!$C$32*(1+Hypothèses!$C$33)^3,0) -> 13 | G23: =ROUND(Hypothèses!$C$32*(1+Hypothèses!$C$33)^4,0) -> 15
A24: Total C — Toiles physiques | B24: C | C24: =C23*Hypothèses!$C$20 -> 15000 | D24: =D23*Hypothèses!$C$20 -> 16500 | E24: =E23*Hypothèses!$C$20 -> 18000 | F24: =F23*Hypothèses!$C$20 -> 19500 | G24: =G23*Hypothèses!$C$20 -> 22500 | H24: =SUM(C24:E24) -> 49500 | I24: =SUM(C24:G24) -> 91500
A25: D. MARCHANDISE / MARQUE
A26: Total D — Marchandise | B26: D | C26: =C5*Hypothèses!$C$34*Hypothèses!$C$21 -> 1200 | D26: =D5*Hypothèses!$C$34*Hypothèses!$C$21 -> 2020 | E26: =E5*Hypothèses!$C$34*Hypothèses!$C$21 -> 2707 | F26: =F5*Hypothèses!$C$34*Hypothèses!$C$21 -> 2947.45 | G26: =G5*Hypothèses!$C$34*Hypothèses!$C$21 -> 3431.6075 | H26: =SUM(C26:E26) -> 5927 | I26: =SUM(C26:G26) -> 12306.058
A27: E. LIEUX THÉMATIQUES (croisière, sports, casino-lieu NFT sans jeu d'argent)
A28: Total E — Passes NFT de lieux + commandites | B28: E | C28: =Hypothèses!B$51*(C5*Hypothèses!$C$35*Hypothèses!$C$22+Hypothèses!$C$36) -> 0 | D28: =Hypothèses!C$51*(D5*Hypothèses!$C$35*Hypothèses!$C$22+Hypothèses!$C$36) -> 0 | E28: =Hypothèses!D$51*(E5*Hypothèses!$C$35*Hypothèses!$C$22+Hypothèses!$C$36) -> 1624.2 | F28: =Hypothèses!E$51*(F5*Hypothèses!$C$35*Hypothèses!$C$22+Hypothèses!$C$36) -> 3536.94 | G28: =Hypothèses!F$51*(G5*Hypothèses!$C$35*Hypothèses!$C$22+Hypothèses!$C$36) -> 6176.8935 | H28: =SUM(C28:E28) -> 1624.2 | I28: =SUM(C28:G28) -> 11338.033
A29: TOTAUX
A30: REVENU BRUT TOTAL (A+B+C+D+E) | B30: gross | C30: =C11+C21+C24+C26+C28 -> 128482.2 | D30: =D11+D21+D24+D26+D28 -> 164368.01 | E30: =E11+E21+E24+E26+E28 -> 200650.12 | F30: =F11+F21+F24+F26+F28 -> 208018.04 | G30: =G11+G21+G24+G26+G28 -> 246156.75 | H30: =SUM(C30:E30) -> 493500.33 | I30: =SUM(C30:G30) -> 947675.13
A31: − Part PlayStation (30 % sur jeu, DLC, passe) | B31: d_sony | C31: =-(C7+C8+C9)*Hypothèses!$C$45 -> -24055.38 | D31: =-(D7+D8+D9)*Hypothèses!$C$45 -> -32621.373 | E31: =-(E7+E8+E9)*Hypothèses!$C$45 -> -41013.981 | F31: =-(F7+F8+F9)*Hypothèses!$C$45 -> -41327.443 | G31: =-(G7+G8+G9)*Hypothèses!$C$45 -> -49455.615 | H31: =SUM(C31:E31) -> -97690.734 | I31: =SUM(C31:G31) -> -188473.79
A32: − Commissions galeries / plateformes (toiles) | B32: d_gal | C32: =-C24*Hypothèses!$C$46 -> -4500 | D32: =-D24*Hypothèses!$C$46 -> -4950 | E32: =-E24*Hypothèses!$C$46 -> -5400 | F32: =-F24*Hypothèses!$C$46 -> -5850 | G32: =-G24*Hypothèses!$C$46 -> -6750 | H32: =SUM(C32:E32) -> -14850 | I32: =SUM(C32:G32) -> -27450
A33: − Coût de production marchandise | B33: d_merch | C33: =-C26*Hypothèses!$C$47 -> -660 | D33: =-D26*Hypothèses!$C$47 -> -1111 | E33: =-E26*Hypothèses!$C$47 -> -1488.85 | F33: =-F26*Hypothèses!$C$47 -> -1621.0975 | G33: =-G26*Hypothèses!$C$47 -> -1887.3841 | H33: =SUM(C33:E33) -> -3259.85 | I33: =SUM(C33:G33) -> -6768.3316
A34: − Redevances influenceurs (5 % du brut) | B34: d_infl | C34: =-C30*Hypothèses!$C$48 -> -6424.11 | D34: =-D30*Hypothèses!$C$48 -> -8218.4007 | E34: =-E30*Hypothèses!$C$48 -> -10032.506 | F34: =-F30*Hypothèses!$C$48 -> -10400.902 | G34: =-G30*Hypothèses!$C$48 -> -12307.838 | H34: =SUM(C34:E34) -> -24675.017 | I34: =SUM(C34:G34) -> -47383.756
A35: REVENU NET POUR L'ENTREPRISE (avant dépenses d'exploitation et impôts) | B35: net | C35: =C30+SUM(C31:C34) -> 92842.71 | D35: =D30+SUM(D31:D34) -> 117467.24 | E35: =E30+SUM(E31:E34) -> 142714.78 | F35: =F30+SUM(F31:F34) -> 148818.6 | G35: =G30+SUM(G31:G34) -> 175755.92 | H35: =SUM(C35:E35) -> 353024.73 | I35: =SUM(C35:G35) -> 677599.25
A37: Le capital Phase 2 (500 000 $ – 550 000 $ CA) est un investissement : il n'apparaît dans aucune ligne de revenu.
A38: Illustratif, non audité, aucune garantie. Contrats rédigés, non déployés, non audités; jeton non inscrit.

Sheet Normal
A1: Scénario Normal — calcul détaillé ($ CA)
A3: Poste | B3: Réf. | C3: An 1 | D3: An 2 | E3: An 3 | F3: An 4 | G3: An 5 | H3: Cumul 3 ans | I3: Cumul 5 ans
A4: Nouveaux joueurs | B4: new | C4: =Hypothèses!$D$5 -> 15000 | D4: =Hypothèses!$D$6 -> 22000 | E4: =Hypothèses!$D$7 -> 30000 | F4: =Hypothèses!$D$8 -> 35000 | G4: =Hypothèses!$D$9 -> 40000
A5: Joueurs actifs (année précédente x rétention + nouveaux) | B5: active | C5: =C4 -> 15000 | D5: =C5*Hypothèses!$D$10+D4 -> 28750 | E5: =D5*Hypothèses!$D$10+E4 -> 42937.5 | F5: =E5*Hypothèses!$D$10+F4 -> 54321.875 | G5: =F5*Hypothèses!$D$10+G4 -> 64444.844
A6: A. CONSOLE — DOGZIE TOWN
A7: Ventes du jeu | B7: A1 | C7: =C4*Hypothèses!$D$12 -> 374850 | D7: =D4*Hypothèses!$D$12 -> 549780 | E7: =E4*Hypothèses!$D$12 -> 749700 | F7: =F4*Hypothèses!$D$12 -> 874650 | G7: =G4*Hypothèses!$D$12 -> 999600 | H7: =SUM(C7:E7) -> 1674330 | I7: =SUM(C7:G7) -> 3548580
A8: Extensions (DLC) | B8: A2 | C8: =C5*Hypothèses!$D$24*Hypothèses!$D$13*Hypothèses!$D$14 -> 37462.5 | D8: =D5*Hypothèses!$D$24*Hypothèses!$D$13*Hypothèses!$D$14 -> 71803.125 | E8: =E5*Hypothèses!$D$24*Hypothèses!$D$13*Hypothèses!$D$14 -> 107236.41 | F8: =F5*Hypothèses!$D$24*Hypothèses!$D$13*Hypothèses!$D$14 -> 135668.88 | G8: =G5*Hypothèses!$D$24*Hypothèses!$D$13*Hypothèses!$D$14 -> 160951 | H8: =SUM(C8:E8) -> 216502.03 | I8: =SUM(C8:G8) -> 513121.91
A9: Passe compétitive multijoueur | B9: A3 | C9: =C5*Hypothèses!$D$25*Hypothèses!$D$15 -> 7191 | D9: =D5*Hypothèses!$D$25*Hypothèses!$D$15 -> 13782.75 | E9: =E5*Hypothèses!$D$25*Hypothèses!$D$15 -> 20584.237 | F9: =F5*Hypothèses!$D$25*Hypothèses!$D$15 -> 26041.907 | G9: =G5*Hypothèses!$D$25*Hypothèses!$D$15 -> 30894.858 | H9: =SUM(C9:E9) -> 41557.988 | I9: =SUM(C9:G9) -> 98494.752
A10: Accessoires / cosmétiques (payés en Dogzy, valeur $ CA) | B10: A4 | C10: =C5*Hypothèses!$D$26*Hypothèses!$D$16 -> 27000 | D10: =D5*Hypothèses!$D$26*Hypothèses!$D$16 -> 51750 | E10: =E5*Hypothèses!$D$26*Hypothèses!$D$16 -> 77287.5 | F10: =F5*Hypothèses!$D$26*Hypothèses!$D$16 -> 97779.375 | G10: =G5*Hypothèses!$D$26*Hypothèses!$D$16 -> 116000.72 | H10: =SUM(C10:E10) -> 156037.5 | I10: =SUM(C10:G10) -> 369817.59
A11: Total A | B11: A | C11: =SUM(C7:C10) -> 446503.5 | D11: =SUM(D7:D10) -> 687115.88 | E11: =SUM(E7:E10) -> 954808.14 | F11: =SUM(F7:F10) -> 1134140.2 | G11: =SUM(G7:G10) -> 1307446.6 | H11: =SUM(C11:E11) -> 2088427.5 | I11: =SUM(C11:G11) -> 4530014.3
A12: B. BLOCKCHAIN — DOGZIE UNIVERSE
A13: NFT personnages vendus (nb) | B13: B1m | C13: =C5*Hypothèses!$D$27+Hypothèses!$D$28 -> 600 | D13: =D5*Hypothèses!$D$27+Hypothèses!$D$28 -> 875 | E13: =E5*Hypothèses!$D$27+Hypothèses!$D$28 -> 1158.75 | F13: =F5*Hypothèses!$D$27+Hypothèses!$D$28 -> 1386.4375 | G13: =G5*Hypothèses!$D$27+Hypothèses!$D$28 -> 1588.8969
A14: Détenteurs cumulés (nb) | B14: hold | C14: =C13 -> 600 | D14: =C14+D13 -> 1475 | E14: =D14+E13 -> 2633.75 | F14: =E14+F13 -> 4020.1875 | G14: =F14+G13 -> 5609.0844
A15: NFT personnages | B15: B1 | C15: =C13*Hypothèses!$D$17 -> 45000 | D15: =D13*Hypothèses!$D$17 -> 65625 | E15: =E13*Hypothèses!$D$17 -> 86906.25 | F15: =F13*Hypothèses!$D$17 -> 103982.81 | G15: =G13*Hypothèses!$D$17 -> 119167.27 | H15: =SUM(C15:E15) -> 197531.25 | I15: =SUM(C15:G15) -> 420681.33
A16: NFT bâtiments / carte | B16: B2 | C16: =Hypothèses!$D$29*Hypothèses!$D$18 -> 8750 | D16: =Hypothèses!$D$29*Hypothèses!$D$18 -> 8750 | E16: =Hypothèses!$D$29*Hypothèses!$D$18 -> 8750 | F16: =Hypothèses!$D$29*Hypothèses!$D$18 -> 8750 | G16: =Hypothèses!$D$29*Hypothèses!$D$18 -> 8750 | H16: =SUM(C16:E16) -> 26250 | I16: =SUM(C16:G16) -> 43750
A17: Éditions Valkyrie par collection (nb) | B17: B3e | C17: =ROUND(Hypothèses!$D$30*(1+Hypothèses!$D$31)^0,0) -> 25 | D17: =ROUND(Hypothèses!$D$30*(1+Hypothèses!$D$31)^1,0) -> 30 | E17: =ROUND(Hypothèses!$D$30*(1+Hypothèses!$D$31)^2,0) -> 36 | F17: =ROUND(Hypothèses!$D$30*(1+Hypothèses!$D$31)^3,0) -> 43 | G17: =ROUND(Hypothèses!$D$30*(1+Hypothèses!$D$31)^4,0) -> 52
A18: Collections NFT mensuelles Valkyrie (12 / an) | B18: B3 | C18: =12*C17*Hypothèses!$D$19 -> 30000 | D18: =12*D17*Hypothèses!$D$19 -> 36000 | E18: =12*E17*Hypothèses!$D$19 -> 43200 | F18: =12*F17*Hypothèses!$D$19 -> 51600 | G18: =12*G17*Hypothèses!$D$19 -> 62400 | H18: =SUM(C18:E18) -> 109200 | I18: =SUM(C18:G18) -> 223200
A19: Redevances sur reventes secondaires | B19: B4 | C19: =(SUM($C15:C15)+SUM($C16:C16)+SUM($C18:C18))*Hypothèses!$D$37*Hypothèses!$D$40 -> 1675 | D19: =(SUM($C15:D15)+SUM($C16:D16)+SUM($C18:D18))*Hypothèses!$D$37*Hypothèses!$D$40 -> 3882.5 | E19: =(SUM($C15:E15)+SUM($C16:E16)+SUM($C18:E18))*Hypothèses!$D$37*Hypothèses!$D$40 -> 6659.625 | F19: =(SUM($C15:F15)+SUM($C16:F16)+SUM($C18:F18))*Hypothèses!$D$37*Hypothèses!$D$40 -> 9946.2812 | G19: =(SUM($C15:G15)+SUM($C16:G16)+SUM($C18:G18))*Hypothèses!$D$37*Hypothèses!$D$40 -> 13752.627 | H19: =SUM(C19:E19) -> 12217.125 | I19: =SUM(C19:G19) -> 35916.033
A20: Frais de plateforme (export de jetons + revente d'accessoires) | B20: B5 | C20: =C14*Hypothèses!$D$38*Hypothèses!$D$41*Hypothèses!$D$42+C10*Hypothèses!$D$43*Hypothèses!$D$44 -> 231 | D20: =D14*Hypothèses!$D$38*Hypothèses!$D$41*Hypothèses!$D$42+D10*Hypothèses!$D$43*Hypothèses!$D$44 -> 494.75 | E20: =E14*Hypothèses!$D$38*Hypothèses!$D$41*Hypothèses!$D$42+E10*Hypothèses!$D$43*Hypothèses!$D$44 -> 807.8375 | F20: =F14*Hypothèses!$D$38*Hypothèses!$D$41*Hypothèses!$D$42+F10*Hypothèses!$D$43*Hypothèses!$D$44 -> 1132.1269 | G20: =G14*Hypothèses!$D$38*Hypothèses!$D$41*Hypothèses!$D$42+G10*Hypothèses!$D$43*Hypothèses!$D$44 -> 1477.4571 | H20: =SUM(C20:E20) -> 1533.5875 | I20: =SUM(C20:G20) -> 4143.1715
A21: Total B | B21: B | C21: =C15+C16+C18+C19+C20 -> 85656 | D21: =D15+D16+D18+D19+D20 -> 114752.25 | E21: =E15+E16+E18+E19+E20 -> 146323.71 | F21: =F15+F16+F18+F19+F20 -> 175411.22 | G21: =G15+G16+G18+G19+G20 -> 205547.35 | H21: =SUM(C21:E21) -> 346731.96 | I21: =SUM(C21:G21) -> 727690.53
A22: C. ART PHYSIQUE — GALERIE VALKYRIE
A23: Toiles vendues (nb) | B23: Cn | C23: =ROUND(Hypothèses!$D$32*(1+Hypothèses!$D$33)^0,0) -> 18 | D23: =ROUND(Hypothèses!$D$32*(1+Hypothèses!$D$33)^1,0) -> 21 | E23: =ROUND(Hypothèses!$D$32*(1+Hypothèses!$D$33)^2,0) -> 24 | F23: =ROUND(Hypothèses!$D$32*(1+Hypothèses!$D$33)^3,0) -> 27 | G23: =ROUND(Hypothèses!$D$32*(1+Hypothèses!$D$33)^4,0) -> 31
A24: Total C — Toiles physiques | B24: C | C24: =C23*Hypothèses!$D$20 -> 27000 | D24: =D23*Hypothèses!$D$20 -> 31500 | E24: =E23*Hypothèses!$D$20 -> 36000 | F24: =F23*Hypothèses!$D$20 -> 40500 | G24: =G23*Hypothèses!$D$20 -> 46500 | H24: =SUM(C24:E24) -> 94500 | I24: =SUM(C24:G24) -> 181500
A25: D. MARCHANDISE / MARQUE
A26: Total D — Marchandise | B26: D | C26: =C5*Hypothèses!$D$34*Hypothèses!$D$21 -> 12000 | D26: =D5*Hypothèses!$D$34*Hypothèses!$D$21 -> 23000 | E26: =E5*Hypothèses!$D$34*Hypothèses!$D$21 -> 34350 | F26: =F5*Hypothèses!$D$34*Hypothèses!$D$21 -> 43457.5 | G26: =G5*Hypothèses!$D$34*Hypothèses!$D$21 -> 51555.875 | H26: =SUM(C26:E26) -> 69350 | I26: =SUM(C26:G26) -> 164363.38
A27: E. LIEUX THÉMATIQUES (croisière, sports, casino-lieu NFT sans jeu d'argent)
A28: Total E — Passes NFT de lieux + commandites | B28: E | C28: =Hypothèses!B$51*(C5*Hypothèses!$D$35*Hypothèses!$D$22+Hypothèses!$D$36) -> 0 | D28: =Hypothèses!C$51*(D5*Hypothèses!$D$35*Hypothèses!$D$22+Hypothèses!$D$36) -> 0 | E28: =Hypothèses!D$51*(E5*Hypothèses!$D$35*Hypothèses!$D$22+Hypothèses!$D$36) -> 30610 | F28: =Hypothèses!E$51*(F5*Hypothèses!$D$35*Hypothèses!$D$22+Hypothèses!$D$36) -> 72149 | G28: =Hypothèses!F$51*(G5*Hypothèses!$D$35*Hypothèses!$D$22+Hypothèses!$D$36) -> 122800.57 | H28: =SUM(C28:E28) -> 30610 | I28: =SUM(C28:G28) -> 225559.58
A29: TOTAUX
A30: REVENU BRUT TOTAL (A+B+C+D+E) | B30: gross | C30: =C11+C21+C24+C26+C28 -> 571159.5 | D30: =D11+D21+D24+D26+D28 -> 856368.12 | E30: =E11+E21+E24+E26+E28 -> 1202091.9 | F30: =F11+F21+F24+F26+F28 -> 1465657.9 | G30: =G11+G21+G24+G26+G28 -> 1733850.4 | H30: =SUM(C30:E30) -> 2629619.5 | I30: =SUM(C30:G30) -> 5829127.7
A31: − Part PlayStation (30 % sur jeu, DLC, passe) | B31: d_sony | C31: =-(C7+C8+C9)*Hypothèses!$D$45 -> -125851.05 | D31: =-(D7+D8+D9)*Hypothèses!$D$45 -> -190609.76 | E31: =-(E7+E8+E9)*Hypothèses!$D$45 -> -263256.19 | F31: =-(F7+F8+F9)*Hypothèses!$D$45 -> -310908.24 | G31: =-(G7+G8+G9)*Hypothèses!$D$45 -> -357433.76 | H31: =SUM(C31:E31) -> -579717.01 | I31: =SUM(C31:G31) -> -1248059
A32: − Commissions galeries / plateformes (toiles) | B32: d_gal | C32: =-C24*Hypothèses!$D$46 -> -8100 | D32: =-D24*Hypothèses!$D$46 -> -9450 | E32: =-E24*Hypothèses!$D$46 -> -10800 | F32: =-F24*Hypothèses!$D$46 -> -12150 | G32: =-G24*Hypothèses!$D$46 -> -13950 | H32: =SUM(C32:E32) -> -28350 | I32: =SUM(C32:G32) -> -54450
A33: − Coût de production marchandise | B33: d_merch | C33: =-C26*Hypothèses!$D$47 -> -6600 | D33: =-D26*Hypothèses!$D$47 -> -12650 | E33: =-E26*Hypothèses!$D$47 -> -18892.5 | F33: =-F26*Hypothèses!$D$47 -> -23901.625 | G33: =-G26*Hypothèses!$D$47 -> -28355.731 | H33: =SUM(C33:E33) -> -38142.5 | I33: =SUM(C33:G33) -> -90399.856
A34: − Redevances influenceurs (5 % du brut) | B34: d_infl | C34: =-C30*Hypothèses!$D$48 -> -28557.975 | D34: =-D30*Hypothèses!$D$48 -> -42818.406 | E34: =-E30*Hypothèses!$D$48 -> -60104.593 | F34: =-F30*Hypothèses!$D$48 -> -73282.894 | G34: =-G30*Hypothèses!$D$48 -> -86692.519 | H34: =SUM(C34:E34) -> -131480.97 | I34: =SUM(C34:G34) -> -291456.39
A35: REVENU NET POUR L'ENTREPRISE (avant dépenses d'exploitation et impôts) | B35: net | C35: =C30+SUM(C31:C34) -> 402050.47 | D35: =D30+SUM(D31:D34) -> 600839.96 | E35: =E30+SUM(E31:E34) -> 849038.57 | F35: =F30+SUM(F31:F34) -> 1045415.1 | G35: =G30+SUM(G31:G34) -> 1247418.4 | H35: =SUM(C35:E35) -> 1851929 | I35: =SUM(C35:G35) -> 4144762.5
A37: Le capital Phase 2 (500 000 $ – 550 000 $ CA) est un investissement : il n'apparaît dans aucune ligne de revenu.
A38: Illustratif, non audité, aucune garantie. Contrats rédigés, non déployés, non audités; jeton non inscrit.

Sheet Optimiste
A1: Scénario Optimiste — calcul détaillé ($ CA)
A3: Poste | B3: Réf. | C3: An 1 | D3: An 2 | E3: An 3 | F3: An 4 | G3: An 5 | H3: Cumul 3 ans | I3: Cumul 5 ans
A4: Nouveaux joueurs | B4: new | C4: =Hypothèses!$E$5 -> 60000 | D4: =Hypothèses!$E$6 -> 110000 | E4: =Hypothèses!$E$7 -> 160000 | F4: =Hypothèses!$E$8 -> 200000 | G4: =Hypothèses!$E$9 -> 230000
A5: Joueurs actifs (année précédente x rétention + nouveaux) | B5: active | C5: =C4 -> 60000 | D5: =C5*Hypothèses!$E$10+D4 -> 143000 | E5: =D5*Hypothèses!$E$10+E4 -> 238650 | F5: =E5*Hypothèses!$E$10+F4 -> 331257.5 | G5: =F5*Hypothèses!$E$10+G4 -> 412191.62
A6: A. CONSOLE — DOGZIE TOWN
A7: Ventes du jeu | B7: A1 | C7: =C4*Hypothèses!$E$12 -> 1499400 | D7: =D4*Hypothèses!$E$12 -> 2748900 | E7: =E4*Hypothèses!$E$12 -> 3998400 | F7: =F4*Hypothèses!$E$12 -> 4998000 | G7: =G4*Hypothèses!$E$12 -> 5747700 | H7: =SUM(C7:E7) -> 8246700 | I7: =SUM(C7:G7) -> 18992400
A8: Extensions (DLC) | B8: A2 | C8: =C5*Hypothèses!$E$24*Hypothèses!$E$13*Hypothèses!$E$14 -> 209790 | D8: =D5*Hypothèses!$E$24*Hypothèses!$E$13*Hypothèses!$E$14 -> 499999.5 | E8: =E5*Hypothèses!$E$24*Hypothèses!$E$13*Hypothèses!$E$14 -> 834439.72 | F8: =F5*Hypothèses!$E$24*Hypothèses!$E$13*Hypothèses!$E$14 -> 1158241.8 | G8: =G5*Hypothèses!$E$24*Hypothèses!$E$13*Hypothèses!$E$14 -> 1441228 | H8: =SUM(C8:E8) -> 1544229.2 | I8: =SUM(C8:G8) -> 4143699.1
A9: Passe compétitive multijoueur | B9: A3 | C9: =C5*Hypothèses!$E$25*Hypothèses!$E$15 -> 47940 | D9: =D5*Hypothèses!$E$25*Hypothèses!$E$15 -> 114257 | E9: =E5*Hypothèses!$E$25*Hypothèses!$E$15 -> 190681.35 | F9: =F5*Hypothèses!$E$25*Hypothèses!$E$15 -> 264674.74 | G9: =G5*Hypothèses!$E$25*Hypothèses!$E$15 -> 329341.11 | H9: =SUM(C9:E9) -> 352878.35 | I9: =SUM(C9:G9) -> 946894.2
A10: Accessoires / cosmétiques (payés en Dogzy, valeur $ CA) | B10: A4 | C10: =C5*Hypothèses!$E$26*Hypothèses!$E$16 -> 180000 | D10: =D5*Hypothèses!$E$26*Hypothèses!$E$16 -> 429000 | E10: =E5*Hypothèses!$E$26*Hypothèses!$E$16 -> 715950 | F10: =F5*Hypothèses!$E$26*Hypothèses!$E$16 -> 993772.5 | G10: =G5*Hypothèses!$E$26*Hypothèses!$E$16 -> 1236574.9 | H10: =SUM(C10:E10) -> 1324950 | I10: =SUM(C10:G10) -> 3555297.4
A11: Total A | B11: A | C11: =SUM(C7:C10) -> 1937130 | D11: =SUM(D7:D10) -> 3792156.5 | E11: =SUM(E7:E10) -> 5739471.1 | F11: =SUM(F7:F10) -> 7414689.1 | G11: =SUM(G7:G10) -> 8754844 | H11: =SUM(C11:E11) -> 11468758 | I11: =SUM(C11:G11) -> 27638291
A12: B. BLOCKCHAIN — DOGZIE UNIVERSE
A13: NFT personnages vendus (nb) | B13: B1m | C13: =C5*Hypothèses!$E$27+Hypothèses!$E$28 -> 2400 | D13: =D5*Hypothèses!$E$27+Hypothèses!$E$28 -> 4890 | E13: =E5*Hypothèses!$E$27+Hypothèses!$E$28 -> 7759.5 | F13: =F5*Hypothèses!$E$27+Hypothèses!$E$28 -> 10537.725 | G13: =G5*Hypothèses!$E$27+Hypothèses!$E$28 -> 12965.749
A14: Détenteurs cumulés (nb) | B14: hold | C14: =C13 -> 2400 | D14: =C14+D13 -> 7290 | E14: =D14+E13 -> 15049.5 | F14: =E14+F13 -> 25587.225 | G14: =F14+G13 -> 38552.974
A15: NFT personnages | B15: B1 | C15: =C13*Hypothèses!$E$17 -> 180000 | D15: =D13*Hypothèses!$E$17 -> 366750 | E15: =E13*Hypothèses!$E$17 -> 581962.5 | F15: =F13*Hypothèses!$E$17 -> 790329.38 | G15: =G13*Hypothèses!$E$17 -> 972431.16 | H15: =SUM(C15:E15) -> 1128712.5 | I15: =SUM(C15:G15) -> 2891473
A16: NFT bâtiments / carte | B16: B2 | C16: =Hypothèses!$E$29*Hypothèses!$E$18 -> 15750 | D16: =Hypothèses!$E$29*Hypothèses!$E$18 -> 15750 | E16: =Hypothèses!$E$29*Hypothèses!$E$18 -> 15750 | F16: =Hypothèses!$E$29*Hypothèses!$E$18 -> 15750 | G16: =Hypothèses!$E$29*Hypothèses!$E$18 -> 15750 | H16: =SUM(C16:E16) -> 47250 | I16: =SUM(C16:G16) -> 78750
A17: Éditions Valkyrie par collection (nb) | B17: B3e | C17: =ROUND(Hypothèses!$E$30*(1+Hypothèses!$E$31)^0,0) -> 60 | D17: =ROUND(Hypothèses!$E$30*(1+Hypothèses!$E$31)^1,0) -> 78 | E17: =ROUND(Hypothèses!$E$30*(1+Hypothèses!$E$31)^2,0) -> 101 | F17: =ROUND(Hypothèses!$E$30*(1+Hypothèses!$E$31)^3,0) -> 132 | G17: =ROUND(Hypothèses!$E$30*(1+Hypothèses!$E$31)^4,0) -> 171
A18: Collections NFT mensuelles Valkyrie (12 / an) | B18: B3 | C18: =12*C17*Hypothèses!$E$19 -> 72000 | D18: =12*D17*Hypothèses!$E$19 -> 93600 | E18: =12*E17*Hypothèses!$E$19 -> 121200 | F18: =12*F17*Hypothèses!$E$19 -> 158400 | G18: =12*G17*Hypothèses!$E$19 -> 205200 | H18: =SUM(C18:E18) -> 286800 | I18: =SUM(C18:G18) -> 650400
A19: Redevances sur reventes secondaires | B19: B4 | C19: =(SUM($C15:C15)+SUM($C16:C16)+SUM($C18:C18))*Hypothèses!$E$37*Hypothèses!$E$40 -> 8032.5 | D19: =(SUM($C15:D15)+SUM($C16:D16)+SUM($C18:D18))*Hypothèses!$E$37*Hypothèses!$E$40 -> 22315.5 | E19: =(SUM($C15:E15)+SUM($C16:E16)+SUM($C18:E18))*Hypothèses!$E$37*Hypothèses!$E$40 -> 43882.875 | F19: =(SUM($C15:F15)+SUM($C16:F16)+SUM($C18:F18))*Hypothèses!$E$37*Hypothèses!$E$40 -> 72817.256 | G19: =(SUM($C15:G15)+SUM($C16:G16)+SUM($C18:G18))*Hypothèses!$E$37*Hypothèses!$E$40 -> 108618.69 | H19: =SUM(C19:E19) -> 74230.875 | I19: =SUM(C19:G19) -> 255666.82
A20: Frais de plateforme (export de jetons + revente d'accessoires) | B20: B5 | C20: =C14*Hypothèses!$E$38*Hypothèses!$E$41*Hypothèses!$E$42+C10*Hypothèses!$E$43*Hypothèses!$E$44 -> 1380 | D20: =D14*Hypothèses!$E$38*Hypothèses!$E$41*Hypothèses!$E$42+D10*Hypothèses!$E$43*Hypothèses!$E$44 -> 3603 | E20: =E14*Hypothèses!$E$38*Hypothèses!$E$41*Hypothèses!$E$42+E10*Hypothèses!$E$43*Hypothèses!$E$44 -> 6589.65 | F20: =F14*Hypothèses!$E$38*Hypothèses!$E$41*Hypothèses!$E$42+F10*Hypothèses!$E$43*Hypothèses!$E$44 -> 10086.308 | G20: =G14*Hypothèses!$E$38*Hypothèses!$E$41*Hypothèses!$E$42+G10*Hypothèses!$E$43*Hypothèses!$E$44 -> 13893.469 | H20: =SUM(C20:E20) -> 11572.65 | I20: =SUM(C20:G20) -> 35552.427
A21: Total B | B21: B | C21: =C15+C16+C18+C19+C20 -> 277162.5 | D21: =D15+D16+D18+D19+D20 -> 502018.5 | E21: =E15+E16+E18+E19+E20 -> 769385.03 | F21: =F15+F16+F18+F19+F20 -> 1047382.9 | G21: =G15+G16+G18+G19+G20 -> 1315893.3 | H21: =SUM(C21:E21) -> 1548566 | I21: =SUM(C21:G21) -> 3911842.3
A22: C. ART PHYSIQUE — GALERIE VALKYRIE
A23: Toiles vendues (nb) | B23: Cn | C23: =ROUND(Hypothèses!$E$32*(1+Hypothèses!$E$33)^0,0) -> 30 | D23: =ROUND(Hypothèses!$E$32*(1+Hypothèses!$E$33)^1,0) -> 38 | E23: =ROUND(Hypothèses!$E$32*(1+Hypothèses!$E$33)^2,0) -> 47 | F23: =ROUND(Hypothèses!$E$32*(1+Hypothèses!$E$33)^3,0) -> 59 | G23: =ROUND(Hypothèses!$E$32*(1+Hypothèses!$E$33)^4,0) -> 73
A24: Total C — Toiles physiques | B24: C | C24: =C23*Hypothèses!$E$20 -> 45000 | D24: =D23*Hypothèses!$E$20 -> 57000 | E24: =E23*Hypothèses!$E$20 -> 70500 | F24: =F23*Hypothèses!$E$20 -> 88500 | G24: =G23*Hypothèses!$E$20 -> 109500 | H24: =SUM(C24:E24) -> 172500 | I24: =SUM(C24:G24) -> 370500
A25: D. MARCHANDISE / MARQUE
A26: Total D — Marchandise | B26: D | C26: =C5*Hypothèses!$E$34*Hypothèses!$E$21 -> 72000 | D26: =D5*Hypothèses!$E$34*Hypothèses!$E$21 -> 171600 | E26: =E5*Hypothèses!$E$34*Hypothèses!$E$21 -> 286380 | F26: =F5*Hypothèses!$E$34*Hypothèses!$E$21 -> 397509 | G26: =G5*Hypothèses!$E$34*Hypothèses!$E$21 -> 494629.95 | H26: =SUM(C26:E26) -> 529980 | I26: =SUM(C26:G26) -> 1422118.9
A27: E. LIEUX THÉMATIQUES (croisière, sports, casino-lieu NFT sans jeu d'argent)
A28: Total E — Passes NFT de lieux + commandites | B28: E | C28: =Hypothèses!B$51*(C5*Hypothèses!$E$35*Hypothèses!$E$22+Hypothèses!$E$36) -> 0 | D28: =Hypothèses!C$51*(D5*Hypothèses!$E$35*Hypothèses!$E$22+Hypothèses!$E$36) -> 0 | E28: =Hypothèses!D$51*(E5*Hypothèses!$E$35*Hypothèses!$E$22+Hypothèses!$E$36) -> 211828 | F28: =Hypothèses!E$51*(F5*Hypothèses!$E$35*Hypothèses!$E$22+Hypothèses!$E$36) -> 557010.8 | G28: =Hypothèses!F$51*(G5*Hypothèses!$E$35*Hypothèses!$E$22+Hypothèses!$E$36) -> 1010333.9 | H28: =SUM(C28:E28) -> 211828 | I28: =SUM(C28:G28) -> 1779172.7
A29: TOTAUX
A30: REVENU BRUT TOTAL (A+B+C+D+E) | B30: gross | C30: =C11+C21+C24+C26+C28 -> 2331292.5 | D30: =D11+D21+D24+D26+D28 -> 4522775 | E30: =E11+E21+E24+E26+E28 -> 7077564.1 | F30: =F11+F21+F24+F26+F28 -> 9505091.8 | G30: =G11+G21+G24+G26+G28 -> 11685201 | H30: =SUM(C30:E30) -> 13931632 | I30: =SUM(C30:G30) -> 35121925
A31: − Part PlayStation (30 % sur jeu, DLC, passe) | B31: d_sony | C31: =-(C7+C8+C9)*Hypothèses!$E$45 -> -527139 | D31: =-(D7+D8+D9)*Hypothèses!$E$45 -> -1008946.9 | E31: =-(E7+E8+E9)*Hypothèses!$E$45 -> -1507056.3 | F31: =-(F7+F8+F9)*Hypothèses!$E$45 -> -1926275 | G31: =-(G7+G8+G9)*Hypothèses!$E$45 -> -2255480.7 | H31: =SUM(C31:E31) -> -3043142.3 | I31: =SUM(C31:G31) -> -7224898
A32: − Commissions galeries / plateformes (toiles) | B32: d_gal | C32: =-C24*Hypothèses!$E$46 -> -13500 | D32: =-D24*Hypothèses!$E$46 -> -17100 | E32: =-E24*Hypothèses!$E$46 -> -21150 | F32: =-F24*Hypothèses!$E$46 -> -26550 | G32: =-G24*Hypothèses!$E$46 -> -32850 | H32: =SUM(C32:E32) -> -51750 | I32: =SUM(C32:G32) -> -111150
A33: − Coût de production marchandise | B33: d_merch | C33: =-C26*Hypothèses!$E$47 -> -39600 | D33: =-D26*Hypothèses!$E$47 -> -94380 | E33: =-E26*Hypothèses!$E$47 -> -157509 | F33: =-F26*Hypothèses!$E$47 -> -218629.95 | G33: =-G26*Hypothèses!$E$47 -> -272046.47 | H33: =SUM(C33:E33) -> -291489 | I33: =SUM(C33:G33) -> -782165.42
A34: − Redevances influenceurs (5 % du brut) | B34: d_infl | C34: =-C30*Hypothèses!$E$48 -> -116564.62 | D34: =-D30*Hypothèses!$E$48 -> -226138.75 | E34: =-E30*Hypothèses!$E$48 -> -353878.21 | F34: =-F30*Hypothèses!$E$48 -> -475254.59 | G34: =-G30*Hypothèses!$E$48 -> -584260.06 | H34: =SUM(C34:E34) -> -696581.58 | I34: =SUM(C34:G34) -> -1756096.2
A35: REVENU NET POUR L'ENTREPRISE (avant dépenses d'exploitation et impôts) | B35: net | C35: =C30+SUM(C31:C34) -> 1634488.9 | D35: =D30+SUM(D31:D34) -> 3176209.3 | E35: =E30+SUM(E31:E34) -> 5037970.6 | F35: =F30+SUM(F31:F34) -> 6858382.3 | G35: =G30+SUM(G31:G34) -> 8540563.9 | H35: =SUM(C35:E35) -> 9848668.7 | I35: =SUM(C35:G35) -> 25247615
A37: Le capital Phase 2 (500 000 $ – 550 000 $ CA) est un investissement : il n'apparaît dans aucune ligne de revenu.
A38: Illustratif, non audité, aucune garantie. Contrats rédigés, non déployés, non audités; jeton non inscrit.
